Workbook

Sheet Master Targets
A1: Master Target Database
A2: All 74 targets across the IB, Corp Dev, and VC lanes in one view | CBS Class of 2028 | Compiled and expanded Aug 22, 2026
A3: Priority / Status / Next Step mirror the lane tabs live: edit them THERE (yellow columns), not here. Sort or filter this sheet freely; formulas follow. | G3: Targets: | H3: =COUNTA($A$6:$A$79) -> 74 | I3: High priority: | J3: =COUNTIF($I$6:$I$79,"High") -> 0 | K3: In motion: | L3: =SUMPRODUCT(--($J$6:$J$79<>""))-COUNTIF($J$6:$J$79,"Not started")-COUNTIF($J$6:$J$79,"Pass") -> 0
A5: Target | B5: Lane | C5: Tier / Category | D5: HQ | E5: Edge in One Line | F5: Access Channel | G5: Timing | H5: Personal Angle | I5: Priority | J5: Status | K5: Next Step | L5: Next Step Date
A6: PJT Partners | B6: IB | C6: 1 - OCR | D6: New York | E6: Payward's house bank (NinjaTrader, Bitnomial, Reap) plus Core Scientific debtor mandate and $9B co-sell to CoreWeave | F6: OCR presentations and closed lists; RSSG restructuring is a separate MBA-heavy track | G6: Sept-Jan OCR | H6: You are living the process they sell; pitch market-structure conviction, not one client | I6: =IF('IB Targets'!F7="","",'IB Targets'!F7) | J6: =IF('IB Targets'!G7="","",'IB Targets'!G7) | K6: =IF('IB Targets'!K7="","",'IB Targets'!K7) | L6: =IF('IB Targets'!L7="","",'IB Targets'!L7)
A7: Evercore | B7: IB | C7: 1 - OCR | D7: New York | E7: Co-lead FA to Siris on the $4.2B Equiniti sale; largest EB associate class, best raw odds | F7: OCR; consistent CBS hirer | G7: Sept-Jan OCR | H7: Brand plus optionality play; Gol/Smiles is the anchor story | I7: =IF('IB Targets'!F8="","",'IB Targets'!F8) | J7: =IF('IB Targets'!G8="","",'IB Targets'!G8) | K7: =IF('IB Targets'!K8="","",'IB Targets'!K8) | L7: =IF('IB Targets'!L8="","",'IB Targets'!L8)
A8: Moelis | B8: IB | C8: 1 - OCR | D8: New York | E8: Restructuring franchise leader (Voyager, Genesis, BlockFi debtors); Bitfarms buy-side; Core Scientific co-sell | F8: Standard OCR process | G8: Sept-Jan OCR | H8: Rx depth is the counter-cyclical hedge if crypto M&A slows | I8: =IF('IB Targets'!F9="","",'IB Targets'!F9) | J8: =IF('IB Targets'!G9="","",'IB Targets'!G9) | K8: =IF('IB Targets'!K9="","",'IB Targets'!K9) | L8: =IF('IB Targets'!L9="","",'IB Targets'!L9)
A9: Centerview | B9: IB | C9: 1 - OCR | D9: New York | E9: Celsius Ch. 11 debtor banker (~$20M fee allocation); smallest class, most selective | F9: OCR | G9: Sept-Jan OCR | H9: - | I9: =IF('IB Targets'!F10="","",'IB Targets'!F10) | J9: =IF('IB Targets'!G10="","",'IB Targets'!G10) | K9: =IF('IB Targets'!K10="","",'IB Targets'!K10) | L9: =IF('IB Targets'!L10="","",'IB Targets'!L10)
A10: Perella Weinberg | B10: IB | C10: 1 - OCR | D10: New York | E10: FTX debtors and Celsius creditors: the two biggest crypto estates | F10: OCR | G10: Sept-Jan OCR | H10: Ask how the market-structure franchise carries forward post-FTX | I10: =IF('IB Targets'!F11="","",'IB Targets'!F11) | J10: =IF('IB Targets'!G11="","",'IB Targets'!G11) | K10: =IF('IB Targets'!K11="","",'IB Targets'!K11) | L10: =IF('IB Targets'!L11="","",'IB Targets'!L11)
A11: Lazard | B11: IB | C11: 1 - OCR | D11: New York | E11: Co-FA to FTAI on the $1.5B Long Ridge sale to MARA | F11: OCR | G11: Sept-Jan OCR | H11: - | I11: =IF('IB Targets'!F12="","",'IB Targets'!F12) | J11: =IF('IB Targets'!G12="","",'IB Targets'!G12) | K11: =IF('IB Targets'!K12="","",'IB Targets'!K12) | L11: =IF('IB Targets'!L12="","",'IB Targets'!L12)
A12: Houlihan Lokey | B12: IB | C12: 1 - OCR | D12: NYC + LA | E12: Genesis creditors; creditor-side franchise across the 2022-24 crypto bankruptcies | F12: OCR; corporate finance and restructuring tracks | G12: Sept-Jan OCR | H12: - | I12: =IF('IB Targets'!F13="","",'IB Targets'!F13) | J12: =IF('IB Targets'!G13="","",'IB Targets'!G13) | K12: =IF('IB Targets'!K13="","",'IB Targets'!K13) | L12: =IF('IB Targets'!L13="","",'IB Targets'!L13)
A13: Guggenheim | B13: IB | C13: 1 - OCR | D13: New York | E13: Fintech coverage; no disclosed crypto M&A credits 2024-26 | F13: OCR | G13: Sept-Jan OCR | H13: Weakest Tier 1 evidence; only if networking comes cheap | I13: =IF('IB Targets'!F14="","",'IB Targets'!F14) | J13: =IF('IB Targets'!G14="","",'IB Targets'!G14) | K13: =IF('IB Targets'!K14="","",'IB Targets'!K14) | L13: =IF('IB Targets'!L14="","",'IB Targets'!L14)
A14: Jefferies | B14: IB | C14: 1 - OCR | D14: New York | E14: Three sell-sides in 15 months (NinjaTrader, Kiavi, Long Ridge) plus FTX creditors; best evidence-to-odds ratio | F14: OCR; larger associate class than the EBs | G14: Sept-Jan OCR | H14: Their sell-side seats mirror your COR PRIME work from the client side | I14: =IF('IB Targets'!F15="","",'IB Targets'!F15) | J14: =IF('IB Targets'!G15="","",'IB Targets'!G15) | K14: =IF('IB Targets'!K15="","",'IB Targets'!K15) | L14: =IF('IB Targets'!L15="","",'IB Targets'!L15)
A15: Cantor Fitzgerald | B15: IB | C15: 2 - Direct | D15: New York | E15: DAT and de-SPAC co-leader (Twenty One, Securitize) plus Strive buy-side on the $1.4B Semler merger | F15: NYC postings plus direct outreach to the digital assets group | G15: Rolling | H15: Name the Semler mandate in the first note | I15: =IF('IB Targets'!F16="","",'IB Targets'!F16) | J15: =IF('IB Targets'!G16="","",'IB Targets'!G16) | K15: =IF('IB Targets'!K16="","",'IB Targets'!K16) | L15: =IF('IB Targets'!L16="","",'IB Targets'!L16)
A16: FT Partners | B16: IB | C16: 2 - Direct | D16: San Francisco (NYC + London) | E16: #1 crypto sell-side franchise: Deribit, Hidden Road, WonderFi, Equiniti co-lead | F16: Direct via Greenhouse plus outreach to the crypto vertical (founder-led: Steve McLaughlin) | G16: Rolling, post-IBC book | H16: You have built the models their decks run on; diligence the culture with former juniors first | I16: =IF('IB Targets'!F17="","",'IB Targets'!F17) | J16: =IF('IB Targets'!G17="","",'IB Targets'!G17) | K16: =IF('IB Targets'!K17="","",'IB Targets'!K17) | L16: =IF('IB Targets'!L17="","",'IB Targets'!L17)
A17: KBW (Stifel) | B17: IB | C17: 2 - Direct | D17: New York | E17: Stifel advised Riot on Block Mining; KBW crypto skews research and capital markets | F17: Network via FIG alumni | G17: Rolling | H17: Bank-crypto convergence (charters, stablecoin issuers) could re-rate this seat fast | I17: =IF('IB Targets'!F18="","",'IB Targets'!F18) | J17: =IF('IB Targets'!G18="","",'IB Targets'!G18) | K17: =IF('IB Targets'!K18="","",'IB Targets'!K18) | L17: =IF('IB Targets'!L18="","",'IB Targets'!L18)
... A28: Aream & Co | B28: IB | C28: 3 - Network | D28: London | E28: London digital asset boutique; no disclosed 2024-26 mandates surfaced | F28: Network | G28: Opportunistic | H28: Direct London-network play | I28: =IF('IB Targets'!F29="","",'IB Targets'!F29) | J28: =IF('IB Targets'!G29="","",'IB Targets'!G29) | K28: =IF('IB Targets'!K29="","",'IB Targets'!K29) | L28: =IF('IB Targets'!L29="","",'IB Targets'!L29)
A29: Kraken / Payward | B29: Corp Dev | C29: Exchange | D29: SF / remote-first | E29: Most acquisitive buyer in the dataset: 8+ deals in 18 months | F29: Ecosystem network; watch strategy and corp dev postings around the listing | G29: IPO window | H29: Your CoS and interim-CFO-style work is the job description | I29: =IF('Corp Dev Targets'!F6="","",'Corp Dev Targets'!F6) | J29: =IF('Corp Dev Targets'!G6="","",'Corp Dev Targets'!G6) | K29: =IF('Corp Dev Targets'!K6="","",'Corp Dev Targets'!K6) | L29: =IF('Corp Dev Targets'!L6="","",'Corp Dev Targets'!L6)
A30: Coinbase | B30: Corp Dev | C30: Exchange | D30: Remote-first | E30: Deribit ($2.9B) plus banker-less bolt-ons; corp dev and ventures are one org | F30: Fall MBA internship applications plus alumni | G30: Fall cycle | H30: Study the Coinbase Ventures portfolio before interviews | I30: =IF('Corp Dev Targets'!F7="","",'Corp Dev Targets'!F7) | J30: =IF('Corp Dev Targets'!G7="","",'Corp Dev Targets'!G7) | K30: =IF('Corp Dev Targets'!K7="","",'Corp Dev Targets'!K7) | L30: =IF('Corp Dev Targets'!L7="","",'Corp Dev Targets'!L7)
A31: Stripe | B31: Corp Dev | C31: Payments | D31: SF / Dublin | E31: Bridge ($1.1B) and Privy with no bankers disclosed; stablecoin thesis | F31: Warm intros only; no MBA machine | G31: Two-year project | H31: Payments and tokenization story; treat as a relationship build | I31: =IF('Corp Dev Targets'!F8="","",'Corp Dev Targets'!F8) | J31: =IF('Corp Dev Targets'!G8="","",'Corp Dev Targets'!G8) | K31: =IF('Corp Dev Targets'!K8="","",'Corp Dev Targets'!K8) | L31: =IF('Corp Dev Targets'!L8="","",'Corp Dev Targets'!L8)
A32: Ripple | B32: Corp Dev | C32: Infra / Payments | D32: SF (NYC office) | E32: Hidden Road ($1.25B), GTreasury ($1B), Rail, BC Payments; a deal a quarter | F32: Postings plus network; integration experience is the wedge | G32: Rolling | H32: Your Optimus integration work maps directly; prime-brokerage fluency from COR PRIME | I32: =IF('Corp Dev Targets'!F9="","",'Corp Dev Targets'!F9) | J32: =IF('Corp Dev Targets'!G9="","",'Corp Dev Targets'!G9) | K32: =IF('Corp Dev Targets'!K9="","",'Corp Dev Targets'!K9) | L32: =IF('Corp Dev Targets'!L9="","",'Corp Dev Targets'!L9)
A33: Mastercard | B33: Corp Dev | C33: TradFi | D33: Purchase, NY | E33: BVNK up to $1.8B, its biggest crypto deal; Start Path accelerator | F33: Structured MBA recruiting; corp dev and strategy tracks | G33: Fall cycle | H33: Most CBS-accessible corp dev door | I33: =IF('Corp Dev Targets'!F10="","",'Corp Dev Targets'!F10) | J33: =IF('Corp Dev Targets'!G10="","",'Corp Dev Targets'!G10) | K33: =IF('Corp Dev Targets'!K10="","",'Corp Dev Targets'!K10) | L33: =IF('Corp Dev Targets'!L10="","",'Corp Dev Targets'!L10)
A34: Robinhood | B34: Corp Dev | C34: Broker | D34: Menlo Park | E34: Bitstamp, WonderFi, TradePMR; outside banks plus inside corp dev | F34: Postings plus network | G34: Rolling | H34: - | I34: =IF('Corp Dev Targets'!F11="","",'Corp Dev Targets'!F11) | J34: =IF('Corp Dev Targets'!G11="","",'Corp Dev Targets'!G11) | K34: =IF('Corp Dev Targets'!K11="","",'Corp Dev Targets'!K11) | L34: =IF('Corp Dev Targets'!L11="","",'Corp Dev Targets'!L11)
A35: Circle | B35: Corp Dev | C35: Stablecoin | D35: New York (One WTC) | E35: Hashnote and infrastructure bolt-ons; public-company stablecoin consolidation mandate | F35: Postings plus NYC network | G35: Rolling | H35: Stablecoin thesis plus your regulated-product operating history | I35: =IF('Corp Dev Targets'!F12="","",'Corp Dev Targets'!F12) | J35: =IF('Corp Dev Targets'!G12="","",'Corp Dev Targets'!G12) | K35: =IF('Corp Dev Targets'!K12="","",'Corp Dev Targets'!K12) | L35: =IF('Corp Dev Targets'!L12="","",'Corp Dev Targets'!L12)
A36: Figure | B36: Corp Dev | C36: Tokenization | D36: San Francisco | E36: Kiavi ($717M) with Sixth Street; tokenization consolidator | F36: Network via the Kiavi advisor web | G36: Deal-driven | H36: Your ETC Group equity-tokenization platform work is directly relevant | I36: =IF('Corp Dev Targets'!F13="","",'Corp Dev Targets'!F13) | J36: =IF('Corp Dev Targets'!G13="","",'Corp Dev Targets'!G13) | K36: =IF('Corp Dev Targets'!K13="","",'Corp Dev Targets'!K13) | L36: =IF('Corp Dev Targets'!L13="","",'Corp Dev Targets'!L13)
A37: Talos | B37: Corp Dev | C37: Infra (FROZEN) | D37: New York | E37: Cloudwall, Skolem, D3X, Coin Metrics; principal-to-principal, no bankers ever disclosed | F37: POST-CLOSE ONLY: no contact while Project Optimus is live | G37: After Optimus close | H37: The warmest door available afterward; total discipline until signing | I37: =IF('Corp Dev Targets'!F14="","",'Corp Dev Targets'!F14) | J37: =IF('Corp Dev Targets'!G14="","",'Corp Dev Targets'!G14) | K37: =IF('Corp Dev Targets'!K14="","",'Corp Dev Targets'!K14) | L37: =IF('Corp Dev Targets'!L14="","",'Corp Dev Targets'!L14)
A38: Tether | B38: Corp Dev | C38: Stablecoin | D38: El Salvador | E38: Tether Investments: Adecoagro ~70%, Twenty One, mining/AI; largest strategic balance sheet in crypto | F38: Network-only; no conventional corp dev path | G38: Opportunistic | H38: Adecoagro = Brazil-agri + your LatAm M&A lens | I38: =IF('Corp Dev Targets'!F15="","",'Corp Dev Targets'!F15) | J38: =IF('Corp Dev Targets'!G15="","",'Corp Dev Targets'!G15) | K38: =IF('Corp Dev Targets'!K15="","",'Corp Dev Targets'!K15) | L38: =IF('Corp Dev Targets'!L15="","",'Corp Dev Targets'!L15)
A39: Anchorage Digital | B39: Corp Dev | C39: Crypto bank | D39: San Francisco | E39: OCC charter moat; Mountain Protocol (USDM) buy 2025 | F39: Postings + network | G39: Rolling | H39: Charter-bank language matches your regulated-platform seat | I39: =IF('Corp Dev Targets'!F16="","",'Corp Dev Targets'!F16) | J39: =IF('Corp Dev Targets'!G16="","",'Corp Dev Targets'!G16) | K39: =IF('Corp Dev Targets'!K16="","",'Corp Dev Targets'!K16) | L39: =IF('Corp Dev Targets'!L16="","",'Corp Dev Targets'!L16)
A40: FalconX | B40: Corp Dev | C40: Prime broker | D40: San Mateo, CA | E40: Serial: Arbelos 2025; 21Shares deal agreed Oct 2025 (verify close) | F40: Postings + network | G40: Rolling | H40: Prime brokerage + ETP: both your worlds in one seat | I40: =IF('Corp Dev Targets'!F17="","",'Corp Dev Targets'!F17) | J40: =IF('Corp Dev Targets'!G17="","",'Corp Dev Targets'!G17) | K40: =IF('Corp Dev Targets'!K17="","",'Corp Dev Targets'!K17) | L40: =IF('Corp Dev Targets'!L17="","",'Corp Dev Targets'!L17)
... A52: Digital Asset (Canton) | B52: Corp Dev | C52: Market infra | D52: New York | E52: Canton Network; institutional consortium | F52: Institutional hiring; NYC | G52: Rolling | H52: Post-trade market structure | I52: =IF('Corp Dev Targets'!F29="","",'Corp Dev Targets'!F29) | J52: =IF('Corp Dev Targets'!G29="","",'Corp Dev Targets'!G29) | K52: =IF('Corp Dev Targets'!K29="","",'Corp Dev Targets'!K29) | L52: =IF('Corp Dev Targets'!L29="","",'Corp Dev Targets'!L29)
A53: Galaxy Ventures | B53: VC | C53: One-roof | D53: New York | E53: Fund I $175M+ (Jun 2025); stablecoins, payments, tokenization thesis | F53: Same relationship as Galaxy IB; CVF-compatible | G53: CVF Sept; rolling | H53: Your exit comps are their underwriting; one Galaxy relationship, three doors | I53: =IF('VC Targets'!F6="","",'VC Targets'!F6) | J53: =IF('VC Targets'!G6="","",'VC Targets'!G6) | K53: =IF('VC Targets'!K6="","",'VC Targets'!K6) | L53: =IF('VC Targets'!L6="","",'VC Targets'!L6)
A54: Fintech Collective | B54: VC | C54: Fintech VC | D54: New York | E54: Best pure stablecoins/payments thesis fit in NYC; capital markets DNA | F54: Newsletter, Layer One podcast, Stablecon | G54: Rolling | H54: Their capital-markets DNA matches your prime-lending seat | I54: =IF('VC Targets'!F7="","",'VC Targets'!F7) | J54: =IF('VC Targets'!G7="","",'VC Targets'!G7) | K54: =IF('VC Targets'!K7="","",'VC Targets'!K7) | L54: =IF('VC Targets'!L7="","",'VC Targets'!L7)
A55: Archetype | B55: VC | C55: Independent | D55: New York | E55: Fund III $100M+ (Sep 2025); stablecoins, payments infra, crypto x AI | F55: Archebyte podcast, NYC in-person events | G55: Rolling | H55: - | I55: =IF('VC Targets'!F8="","",'VC Targets'!F8) | J55: =IF('VC Targets'!G8="","",'VC Targets'!G8) | K55: =IF('VC Targets'!K8="","",'VC Targets'!K8) | L55: =IF('VC Targets'!L8="","",'VC Targets'!L8)
A56: Variant | B56: VC | C56: Independent | D56: Brooklyn | E56: Variant 4 $222M (Jun 2026); crypto x AI autonomy thesis | F56: Thesis essays; writing-first outreach works here | G56: Rolling | H56: Write your way in; they reward essays | I56: =IF('VC Targets'!F9="","",'VC Targets'!F9) | J56: =IF('VC Targets'!G9="","",'VC Targets'!G9) | K56: =IF('VC Targets'!K9="","",'VC Targets'!K9) | L56: =IF('VC Targets'!L9="","",'VC Targets'!L9)
A57: CoinFund | B57: VC | C57: Independent | D57: Brooklyn | E57: $550M+ across recent vehicles; venture plus liquid; market-structure focus | F57: NYC events plus CVF; research and podcast engagement | G57: CVF Sept | H57: One of the few crypto funds a CBS student can see weekly | I57: =IF('VC Targets'!F10="","",'VC Targets'!F10) | J57: =IF('VC Targets'!G10="","",'VC Targets'!G10) | K57: =IF('VC Targets'!K10="","",'VC Targets'!K10) | L57: =IF('VC Targets'!L10="","",'VC Targets'!L10)
A58: Portal Ventures | B58: VC | C58: Independent | D58: New York | E58: Fund II $75M (late 2024); pre-seed lead checks; fundamentals-driven | F58: Fisher's writing and podcasts; MBA-friendly framing | G58: Rolling | H58: The most MBA-legible framing in the set; hires early-career | I58: =IF('VC Targets'!F11="","",'VC Targets'!F11) | J58: =IF('VC Targets'!G11="","",'VC Targets'!G11) | K58: =IF('VC Targets'!K11="","",'VC Targets'!K11) | L58: =IF('VC Targets'!L11="","",'VC Targets'!L11)
A59: VanEck Ventures | B59: VC | C59: Corporate fund | D59: New York | E59: $30M debut fund; ex-Circle Ventures team; stablecoin/tokenization thesis | F59: Media-active partners; direct outreach viable | G59: Rolling | H59: An ETP operator's story lands at an ETP house: your ETC Group years are the intro | I59: =IF('VC Targets'!F12="","",'VC Targets'!F12) | J59: =IF('VC Targets'!G12="","",'VC Targets'!G12) | K59: =IF('VC Targets'!K12="","",'VC Targets'!K12) | L59: =IF('VC Targets'!L12="","",'VC Targets'!L12)
A60: 6th Man Ventures | B60: VC | C60: Independent | D60: New York | E60: Fund II $145M; consumer and Solana-weighted | F60: Dudas is highly public; NYC events | G60: Rolling | H60: - | I60: =IF('VC Targets'!F13="","",'VC Targets'!F13) | J60: =IF('VC Targets'!G13="","",'VC Targets'!G13) | K60: =IF('VC Targets'!K13="","",'VC Targets'!K13) | L60: =IF('VC Targets'!L13="","",'VC Targets'!L13)
A61: North Island Ventures | B61: VC | C61: Independent | D61: New York | E61: ~$300M AUM; stablecoin payments and interoperability thesis | F61: Scher podcasts; watch for associate openings | G61: Rolling | H61: A live seat to watch, not just a coffee: they have hired associates | I61: =IF('VC Targets'!F14="","",'VC Targets'!F14) | J61: =IF('VC Targets'!G14="","",'VC Targets'!G14) | K61: =IF('VC Targets'!K14="","",'VC Targets'!K14) | L61: =IF('VC Targets'!L14="","",'VC Targets'!L14)
A62: Dragonfly (NYC) | B62: VC | C62: Bicoastal | D62: NYC + Singapore | E62: Fund IV $650M (Feb 2026); RWA and stablecoin pivot; ~$4B AUM | F62: Chopping Block podcast, research | G62: Rolling | H62: Note the DOJ / Tornado Cash caveat on one GP before any outreach there | I62: =IF('VC Targets'!F15="","",'VC Targets'!F15) | J62: =IF('VC Targets'!G15="","",'VC Targets'!G15) | K62: =IF('VC Targets'!K15="","",'VC Targets'!K15) | L62: =IF('VC Targets'!L15="","",'VC Targets'!L15)
...

Sheet IB Targets
A1: IB / M&A Advisory Targets
A2: CBS Class of 2028 | Summer 2027 associate cycle | Tiers: 1 OCR, 2 Direct, 3 Network | Depth on Target Profiles
A3: Fill in the yellow columns (F to M). Row 6 is an example row; overwrite or delete it. | H3: Targets: | I3: =COUNTA($A$7:$A$29) -> 23 | J3: High priority: | K3: =COUNTIF($F$7:$F$29,"High") -> 0 | L3: In motion: | M3: =COUNTA($G$7:$G$29)-COUNTIF($G$7:$G$29,"Not started")-COUNTIF($G$7:$G$29,"Pass") -> 0
A5: Firm | B5: Tier | C5: Crypto / Deal Evidence | D5: Hiring Model | E5: Access Channel | F5: Priority | G5: Status | H5: Contact(s) | I5: Contact Source | J5: Last Contact | K5: Next Step | L5: Next Step Date | M5: Notes
A6: (Example) Firm Name | B6: 1 - OCR | C6: Example row: overwrite or delete | D6: Structured | E6: OCR | F6: High | G6: Outreach sent | H6: Jane Doe, VP FIG | I6: CBS alum ('24) | J6: 46280 | K6: Coffee chat at EIS | L6: 46287 | M6: Met at fintech club event
A7: PJT Partners | B7: 1 - OCR | C7: Payward's house bank (NinjaTrader buy, Bitnomial sell, Reap buy); Core Scientific debtor banker and co-sell to CoreWeave ($9B) | D7: Structured summer associate program | E7: OCR presentations and closed lists; RSSG restructuring track is MBA-heavy
A8: Evercore | B8: 1 - OCR | C8: Co-lead FA to Siris on the $4.2B Equiniti sale; broad fintech franchise | D8: Structured summer associate program | E8: Core OCR name; consistent CBS hirer
A9: Moelis | B9: 1 - OCR | C9: Restructuring franchise leader (Voyager, Genesis, BlockFi debtors); Bitfarms buy-side; Core Scientific co-sell | D9: Structured summer associate program | E9: Standard OCR process
A10: Centerview | B10: 1 - OCR | C10: Celsius Chapter 11 debtor banker (largest banker fee allocation, ~$20M); top-end fintech | D10: Structured summer associate program | E10: OCR; smallest class, most selective of the group
A11: Perella Weinberg | B11: 1 - OCR | C11: FTX debtors banker; Celsius creditors banker; two of the biggest crypto estates | D11: Structured summer associate program | E11: OCR
A12: Lazard | B12: 1 - OCR | C12: Co-FA to FTAI on the $1.5B Long Ridge sale to MARA | D12: Structured summer associate program | E12: OCR
A13: Houlihan Lokey | B13: 1 - OCR | C13: Genesis creditors banker; creditor-side franchise across the crypto bankruptcies | D13: Structured summer associate program | E13: OCR; corporate finance and restructuring tracks
A14: Guggenheim | B14: 1 - OCR | C14: Fintech coverage; no disclosed crypto M&A credits surfaced 2024-26 | D14: Structured summer associate program | E14: OCR
A15: Jefferies | B15: 1 - OCR | C15: Three sell-sides in 15 months (NinjaTrader, Kiavi, FTAI/Long Ridge) plus FTX creditors committee; steadiest non-BB in the space | D15: Structured summer associate program | E15: OCR; larger associate class than the EBs
A16: Cantor Fitzgerald | B16: 2 - Direct | C16: DAT and de-SPAC co-leader (Twenty One, Securitize) plus buy-side FA to Strive on the $1.4B Semler merger; bitcoin financing | D16: Posts roles; less structured MBA path | E16: NYC postings plus direct outreach to the digital assets group
A17: FT Partners | B17: 2 - Direct | C17: #1 crypto sell-side franchise: Deribit, Hidden Road, WonderFi, and Equiniti co-lead; four marquee exits | D17: Direct hiring via Greenhouse; apprenticeship model | E17: Direct application plus targeted outreach; no major OCR presence
A18: KBW (Stifel) | B18: 2 - Direct | C18: Stifel advised Riot on the Block Mining buy; KBW crypto work skews research and capital markets, not M&A | D18: Mostly lateral; selective postings | E18: Network via FIG alumni
... A29: Aream & Co | B29: 3 - Network | C29: London digital asset boutique; no disclosed 2024-26 mandates surfaced in the research | D29: No formal program | E29: Network
A31: Deal evidence from press releases, firm tombstones, SEC filings, and Architect Partners alerts through Aug 21, 2026. Tier 1 runs on the Sept-Jan OCR cycle; Tiers 2 and 3 run rolling and post-close.

Sheet Corp Dev Targets
A1: Corporate Development Targets
A2: The buy side of your Deal Evidence tab | Just-in-time hiring; postings and network, not a cycle | Full acquirer universe on the Corp Dev Universe tab
A3: Fill in the yellow columns (F to M). | H3: Targets: | I3: =COUNTA($A$6:$A$29) -> 24 | J3: High priority: | K3: =COUNTIF($F$6:$F$29,"High") -> 0 | L3: In motion: | M3: =COUNTA($G$6:$G$29)-COUNTIF($G$6:$G$29,"Not started")-COUNTIF($G$6:$G$29,"Pass") -> 0
A5: Firm | B5: Category | C5: Crypto / Deal Evidence | D5: Hiring Model | E5: Access Channel | F5: Priority | G5: Status | H5: Contact(s) | I5: Contact Source | J5: Last Contact | K5: Next Step | L5: Next Step Date | M5: Notes
A6: Kraken / Payward | B6: Exchange | C6: Most acquisitive buyer in the dataset: 8+ deals in 18 months (NinjaTrader, Bitnomial, Reap, Small Exchange, Magna, Magic Labs, Breakout) | D6: Just-in-time; tiny team; pre-IPO equity | E6: Ecosystem network; watch strategy and corp dev postings around the listing
A7: Coinbase | B7: Exchange | C7: Deribit ($2.9B) plus banker-less bolt-ons (Echo, Liquifi, Iron, Spindl); corp dev and ventures combined | D7: Elite in-house shop; runs structured MBA internships | E7: Fall applications plus alumni
A8: Stripe | B8: Payments | C8: Bridge ($1.1B) and Privy with no bankers disclosed; stablecoin thesis | D8: Pure network hiring; no MBA machine | E8: Warm intros only; two-year relationship project
A9: Ripple | B9: Infra / Payments | C9: Hidden Road ($1.25B), GTreasury ($1B), Rail, BC Payments; a deal a quarter on a huge balance sheet | D9: Posts corp dev and integration roles | E9: Postings plus network; integration experience is the wedge
A10: Mastercard | B10: TradFi | C10: BVNK up to $1.8B, its biggest crypto deal; Start Path accelerator | D10: Structured MBA recruiting; corp dev and strategy tracks | E10: Most CBS-accessible corp dev door
A11: Robinhood | B11: Broker | C11: Bitstamp, WonderFi, TradePMR; uses Barclays and JPMorgan outside, corp dev inside | D11: Posts roles; growing team | E11: Postings plus network
A12: Circle | B12: Stablecoin | C12: Hashnote and infrastructure bolt-ons; public company with stablecoin consolidation mandate | D12: Small team; posts roles | E12: Postings plus NYC network
A13: Figure | B13: Tokenization | C13: Kiavi ($717M) with Sixth Street; tokenization consolidator | D13: Small team; deal-driven hiring | E13: Network via the Kiavi advisor web
A14: Talos | B14: Infra (frozen) | C14: Cloudwall, Skolem, D3X, Coin Metrics ($100M+); principal-to-principal, no bankers ever disclosed | D14: Tiny; hires around deals | E14: POST-CLOSE ONLY: no contact while Project Optimus is live; afterward the warmest door available
A15: Tether | B15: Stablecoin | C15: Tether Investments: Adecoagro ~70% tender ($615.5M), Twenty One, mining/AI/media bets; the largest strategic balance sheet in crypto | D15: No conventional corp dev path; network-only | E15: Strategic weight, not a hiring machine; Adecoagro = LatAm angle
A16: Anchorage Digital | B16: Crypto bank | C16: OCC-chartered digital asset bank; bought Mountain Protocol (USDM stablecoin, 2025); institutional custody/settlement | D16: Small corp dev; institutional hiring | E16: Postings + network; charter-bank story
A17: FalconX | B17: Prime broker | C17: Serial acquirer: Arbelos (2025); 21Shares acquisition agreed Oct 2025 (verify close); prime consolidation leader | D17: Real corp dev; growing fast | E17: Postings + network; prime + ETP = both your worlds
... A29: Digital Asset (Canton) | B29: Market infra | C29: NYC; Canton Network with a Goldman/DTCC-adjacent consortium; major 2025 raise | D29: Institutional hiring; NYC | E29: NYC TradFi-crypto door; post-trade + tokenization
A31: Corp dev teams are small (2 to 8 people) and hire around deals; the 'Not disclosed' buy-side cells in Deal Evidence mark the shops that run deals without bankers. Talos row is FROZEN until Project Optimus signs; no outreach of any kind before close. Rows 15-22 added Aug 22, 2026 from general knowledge (Jan 2026 horizon), not the verified research - verify before citing. Full acquirer universe on the Corp Dev Universe tab. Rows 23-29 added Aug 22, 2026 for NYC presence + fit (BlackRock through Digital Asset) - K-sourced except where research-verified; verify before citing.

Sheet Corp Dev Universe
A1: Corp Dev Universe
A2: The full strategic-acquirer universe with NYC reachability | Filter the NYC Presence column to plan coffee-chat range
A3: Src: R = verified Aug 2026 research; K = general knowledge - VERIFY. NYC Presence: HQ / Metro (commutable) / Office / Team / People (individuals based there) / Verify (unconfirmed) / '-' none known. K-confidence, Jan 2026 horizon - confirm before planning outreach around it. Yellow column M is yours. | H3: Entries: | I3: =COUNTA($A$6:$A$144) -> 139
A5: Company | B5: Category | C5: HQ | D5: NYC Presence | E5: Ownership / Ticker | F5: Crypto M&A / Strategic Evidence | G5: Corp Dev & Hiring Reality | H5: MBA Door | I5: Personal Angle | J5: Priority | K5: Src | L5: Notes | M5: Your Flag
A6: Kraken / Payward | B6: Exchange | C6: SF / remote-first | D6: People (verify) | E6: Private (IPO track) | F6: 8+ deals in 18 months: NinjaTrader $1.5B, Bitnomial, Reap, Small Exchange, Magna, Magic Labs, Breakout | G6: Just-in-time; tiny team; pre-IPO equity | H6: Ecosystem network + postings around listing | I6: CoS/interim-CFO profile matches | J6: S1 | K6: R | L6: On Corp Dev Targets tab; On working tab
A7: Coinbase | B7: Exchange | C7: Remote-first | D7: Office | E7: Public (COIN) | F7: Deribit $2.9B; banker-less bolt-ons: Echo, Liquifi, Iron, Spindl | G7: Elite in-house; structured MBA internships | H7: Fall applications + alumni | I7: Study Ventures portfolio first | J7: S1 | K7: R | L7: On Corp Dev Targets tab; On working tab
A8: Stripe | B8: Payments | C8: SF / Dublin | D8: Office | E8: Private | F8: Bridge $1.1B; Privy; stablecoin thesis | G8: Pure network hiring | H8: Warm intros only; 2-year project | I8: Tokenization + payments story | J8: S2 | K8: R | L8: On Corp Dev Targets tab; On working tab
A9: Ripple | B9: Infra / Payments | C9: SF (NYC office) | D9: Office | E9: Private | F9: Hidden Road $1.25B; GTreasury $1B; Rail $200M; BC Payments | G9: Posts corp dev + integration roles | H9: Postings + network | I9: Integration work maps; prime adjacency | J9: S1 | K9: R | L9: On Corp Dev Targets tab; On working tab
A10: Mastercard | B10: Payment network | C10: Purchase, NY | D10: Metro HQ (Purchase) | E10: Public (MA) | F10: BVNK up to $1.8B (closed Aug 2026); Start Path | G10: Structured MBA recruiting | H10: Most CBS-accessible corp dev door | I10: - | J10: S1 | K10: R | L10: On Corp Dev Targets tab; On working tab
A11: Robinhood | B11: Broker | C11: Menlo Park, CA | D11: Office | E11: Public (HOOD) | F11: Bitstamp $200M; WonderFi C$250M; TradePMR | G11: Posts roles; growing team | H11: Postings + network | I11: - | J11: S2 | K11: R | L11: On Corp Dev Targets tab; On working tab
A12: Circle | B12: Stablecoin | C12: New York (One WTC) | D12: HQ | E12: Public (CRCL) | F12: Hashnote; infrastructure bolt-ons; consolidation mandate | G12: Small team; posts roles | H12: Postings + NYC network | I12: Regulated-platform operating history | J12: S1 | K12: R | L12: On Corp Dev Targets tab; On working tab
A13: Figure | B13: Tokenization | C13: San Francisco, CA | D13: Office (verify) | E13: Public (FIGR, verify) | F13: Kiavi $717M with Sixth Street | G13: Small; deal-driven hiring | H13: Network via Kiavi advisor web | I13: ETC tokenization platform work | J13: S2 | K13: R | L13: On Corp Dev Targets tab; On working tab
A14: Talos | B14: Infra (FROZEN) | C14: New York, NY | D14: HQ | E14: Private | F14: Cloudwall, Skolem, D3X, Coin Metrics $100M+; principal-to-principal | G14: Tiny; hires around deals | H14: POST-CLOSE ONLY | I14: Warmest door after Optimus signs | J14: S1 | K14: R | L14: On Corp Dev Targets tab; frozen until close; On working tab
A15: Gemini | B15: Exchange | C15: New York, NY | D15: HQ | E15: Public (GEMI) | F15: IPO Sep 2025 ($425M); acquisitive historically (Nifty era); rebuilding | G15: Small corp dev; NYC HQ | H15: NYC postings + network | I15: Winklevoss Capital same roof | J15: S2 | K15: R | L15: Stock fell post-IPO; $100M insider injection May 2026
A16: Bullish | B16: Exchange / media | C16: NYC + Cayman | D16: HQ | E16: Public (BLSH, verify) | F16: Equiniti $4.2B buy (2026); owns CoinDesk | G16: Building out post-Equiniti | H16: Postings; the Equiniti integration needs people | I16: Integration story = your wedge | J16: S2 | K16: R | L16: Equiniti deal is in your Deal Evidence tab
A17: Crypto.com | B17: Exchange | C17: Singapore | D17: - | E17: Private | F17: Acquisitive history (Watchdog, derivatives licenses, SEC-reg entities) | G17: Global; US corp dev present | H17: Postings | I17: - | J17: S3 | K17: K
A18: OKX | B18: Exchange | C18: Seychelles / San Jose US HQ | D18: Office (verify) | E18: Private | F18: US expansion 2025; license-driven deals | G18: US build-out hiring | H18: US postings | I18: - | J18: S3 | K18: K
A19: eToro | B19: Broker | C19: Israel / NYC | D19: Office (US base) | E19: Public (ETOR) | F19: IPO May 2025; acquisitive history (Gatsby, Deep) | G19: Corp dev exists | H19: Postings | I19: - | J19: S3 | K19: K
A20: Webull | B20: Broker | C20: St. Petersburg, FL | D20: - | E20: Public (BULL) | F20: Re-launched crypto 2025 | G20: Thin crypto corp dev | H20: - | I20: - | J20: Monitor | K20: K
A21: Interactive Brokers | B21: Broker | C21: Greenwich, CT | D21: Metro (Greenwich) | E21: Public (IBKR) | F21: Crypto via Paxos/Zero Hash rails | G21: Strategy more than M&A | H21: Metro-area TradFi door | I21: - | J21: Monitor | K21: K
A22: Charles Schwab | B22: Broker | C22: Westlake, TX | D22: - (corp dev in TX) | E22: Public (SCHW) | F22: Announced direct crypto trading 2025-26; EDX backer | G22: Large corp dev/strategy org | H22: Structured hiring | I22: TradFi-crypto convergence seat | J22: S3 | K22: K
A23: Morgan Stanley / E*Trade | B23: Bank / broker | C23: New York, NY | D23: HQ | E23: Public (MS) | F23: E*Trade crypto launch announced (2025, Zero Hash rails - verify) | G23: Strategy org | H23: Classic MBA door | I23: Convergence thesis | J23: S3 | K23: K
A24: Coincheck Group | B24: Exchange | C24: Tokyo / Nasdaq | D24: - | E24: Public (CNCK) | F24: Aplo buy (2025, Galaxy sell-side); Nasdaq-listed via de-SPAC | G24: Small; Japan + EU | H24: - | I24: Aplo deal in Deal Evidence tab | J24: Monitor | K24: R
A25: Dunamu (Upbit) | B25: Exchange | C25: Seoul, KR | D25: - | E25: Private | F25: Korea's largest; occasional stakes | G25: Korea-based | H25: - | I25: - | J25: Monitor | K25: K
A26: bitFlyer | B26: Exchange | C26: Tokyo, JP | D26: - | E26: Private | F26: Acquired FTX Japan (2024) | G26: Japan | H26: - | I26: - | J26: Monitor | K26: K
A27: SBI Digital Asset Holdings | B27: Exchange / bank group | C27: Tokyo, JP | D27: - | E27: Public (8473.T) | F27: bitbank $289M (2026); B2C2 owner; serial digital-asset buyer | G27: Group-level corp dev | H27: - | I27: bitbank deal in Deal Evidence tab | J27: Monitor | K27: R
A28: Strike (Zap) | B28: Payments / bitcoin | C28: Chicago, IL | D28: - | E28: Private | F28: Jack Mallers; also CEO of Twenty One | G28: Tiny | H28: - | I28: - | J28: Monitor | K28: K
... A30: Block (Square) | B30: Fintech / bitcoin | C30: Oakland, CA | D30: People (verify) | E30: Public (XYZ) | F30: Bitkey, Proto mining rigs, Cash App bitcoin; Afterpay-era M&A muscle | G30: Real corp dev org | H30: Postings; bitcoin-native strategy roles | I30: - | J30: S2 | K30: K
A31: PayPal | B31: Payments | C31: San Jose, CA | D31: Office (Venmo NYC) | E31: Public (PYPL) | F31: PYUSD stablecoin; Curv + Paidy era buys; Ventures arm | G31: Large corp dev; MBA-friendly | H31: Structured recruiting | I31: Stablecoin distribution thesis | J31: S1 | K31: K | L31: Promoted to Corp Dev Targets tab; On working tab
A32: Visa | B32: Payment network | C32: San Francisco, CA | D32: Office | E32: Public (V) | F32: Stablecoin settlement (USDC); Pismo $1B (Brazil); crypto team under Cuy Sheffield | G32: Large corp dev + crypto team | H32: Structured MBA recruiting | I32: Pismo = Brazil angle; stablecoin settlement = thesis | J32: S1 | K32: K | L32: Promoted to Corp Dev Targets tab; On working tab
A33: Fiserv | B33: Payments infra | C33: Milwaukee, WI | D33: Office (First Data legacy) | E33: Public (FI) | F33: FIUSD stablecoin launch (2025); serial acquirer | G33: Big corp dev org | H33: Structured hiring | I33: Stablecoin-meets-legacy-rails story | J33: S3 | K33: K
A34: Western Union | B34: Remittances | C34: Denver, CO | D34: - | E34: Public (WU) | F34: Stablecoin pilots announced 2025 (verify scope) | G34: Corp dev exists | H34: - | I34: Remittance + stablecoin thesis | J34: Monitor | K34: K
A35: MoneyGram | B35: Remittances | C35: Dallas, TX | D35: - | E35: Private (MDP-owned) | F35: Stellar USDC cash rails | G35: - | H35: - | I35: - | J35: Monitor | K35: K
A36: Revolut | B36: Neobank | C36: London, UK | D36: Office (US base NYC) | E36: Private | F36: Large crypto book; occasional bolt-ons | G36: London strategy org | H36: London network | I36: Your London base | J36: S3 | K36: K
A37: Nubank | B37: Neobank | C37: Sao Paulo, BR | D37: - | E37: Public (NU) | F37: Crypto rollout; token bets; minority stakes | G37: Real corp dev; LatAm MBA hiring | H37: Structured + network | I37: Brazil: language, market, network | J37: S2 | K37: K | L37: Promoted to Corp Dev Targets tab; On working tab
A38: Mercado Libre / Mercado Pago | B38: Commerce / fintech | C38: Buenos Aires / Sao Paulo | D38: - | E38: Public (MELI) | F38: Crypto in Mercado Pago; stablecoin interest (Meli Dolar) | G38: Big corp dev; LatAm MBA recruiting | H38: Structured + network | I38: Brazil angle direct | J38: S3 | K38: K
A39: Bitso | B39: Exchange / payments | C39: Mexico City / remote | D39: - | E39: Private | F39: LatAm leader; stablecoin rails (Juno unit) | G39: Small corp dev | H39: Network | I39: LatAm crypto payments = your two worlds | J39: S3 | K39: K
A40: SoFi | B40: Fintech / bank | C40: San Francisco, CA | D40: Office | E40: Public (SOFI) | F40: Re-entered crypto 2025 with bank charter | G40: Corp dev + strategy org | H40: Postings | I40: Charter-bank crypto convergence | J40: S3 | K40: K
A41: dLocal | B41: Payments | C41: Montevideo, UY | D41: - | E41: Public (DLO) | F41: Stablecoin settlement interest (verify) | G41: - | H41: - | I41: LatAm payments | J41: Monitor | K41: K
A42: EBANX | B42: Payments | C42: Curitiba, BR | D42: - | E42: Private | F42: LatAm payments; stablecoin pilots (verify) | G42: - | H42: - | I42: Brazil HQ | J42: Monitor | K42: K
...

Sheet VC Targets
A1: Venture / VC Targets
A2: Verified against the Aug 2026 NYC fund research | Databases: VC Fund Database (NYC detail) + VC Universe (global) | CVF opens ~Aug 28
A3: Fill in the yellow columns (F to M). | H3: Targets: | I3: =COUNTA($A$6:$A$32) -> 27 | J3: High priority: | K3: =COUNTIF($F$6:$F$32,"High") -> 0 | L3: In motion: | M3: =COUNTA($G$6:$G$32)-COUNTIF($G$6:$G$32,"Not started")-COUNTIF($G$6:$G$32,"Pass") -> 0
A5: Fund | B5: Type | C5: Crypto / Deal Evidence | D5: Hiring Model | E5: Access Channel | F5: Priority | G5: Status | H5: Contact(s) | I5: Contact Source | J5: Last Contact | K5: Next Step | L5: Next Step Date | M5: Notes
A6: Galaxy Ventures | B6: One-roof | C6: Fund I $175M+ (Jun 2025); stablecoins, payments, tokenization; leads Will Nuelle and Mike Giampapa | D6: Small team; platform hires | E6: Same relationship as Galaxy IB; CVF-compatible
A7: Fintech Collective | B7: Fintech VC | C7: ~$500M AUM; the single best stablecoins/payments thesis fit in NYC; capital markets DNA | D7: Small team; seed/A checks $500K-4M | E7: Newsletter, Layer One podcast, Stablecon conference
A8: Archetype | B8: Independent | C8: Fund III $100M+ (Sep 2025); stablecoins, payments infra, crypto x AI; Ash Egan, Katherine Wu | D8: Concentrated team; occasional roles | E8: Archebyte podcast, NYC in-person events
A9: Variant | B9: Independent | C9: Variant 4 $222M (Jun 2026); crypto x AI 'autonomy' thesis; Jesse Walden, Li Jin; Brooklyn | D9: Small team | E9: Thesis essays; writing-first outreach works here
A10: CoinFund | B10: Independent | C10: $550M+ raised across recent vehicles; Brooklyn RIA; venture plus liquid; market-structure focus | D10: Small team; has hired early-career | E10: NYC events plus CVF; research and podcast engagement
A11: Portal Ventures | B11: Independent | C11: Fund II $75M (late 2024); pre-seed lead checks; fundamentals-driven; Evan Fisher (ex-Insight) | D11: Small; hires early-career | E11: Fisher's writing and podcasts; MBA-friendly framing
A12: VanEck Ventures | B12: Corporate fund | C12: $30M debut fund (Oct 2024); ex-Circle Ventures team (Lonergan, Lopez); stablecoin/tokenization thesis | D12: Tiny team; accessible | E12: Media-active partners; direct outreach viable
A13: 6th Man Ventures | B13: Independent | C13: Fund II $145M; consumer and Solana-weighted; Mike Dudas (The Block co-founder), Serge Kassardjian | D13: Small team | E13: Dudas is highly public; NYC events
A14: North Island Ventures | B14: Independent | C14: ~$300M AUM; Travis Scher (ex-DCG), Glenn Hutchins; stablecoin payments and interoperability thesis | D14: Small; has advertised associate roles | E14: Scher podcasts; watch for openings
A15: Dragonfly (NYC) | B15: Bicoastal | C15: Fund IV $650M (Feb 2026); RWA and stablecoin pivot; ~$4B AUM; note DOJ/Tornado Cash caveat on one GP | D15: Small NYC bench; occasional roles | E15: Chopping Block podcast, research
A16: Union Square Ventures | B16: Independent | C16: Thesis-driven; early Coinbase backer; still leading crypto rounds in 2025 | D16: Small; has run analyst and fellow programs | E16: CVF plus thoughtful written outreach; they reward writing
A17: Castle Island Ventures | B17: Independent | C17: Backed both Talos and Coin Metrics; Boston HQ (not NYC); founders Nic Carter, Matt Walsh | D17: Small partnership; occasional fellows | E17: Post-close Talos angle; engage On The Brink first
... A32: Index Ventures | B32: Generalist w/ crypto | C32: NYC office; backed Bridge (sold to Stripe, $1.1B) - a live stablecoin credential; deep fintech bench | D32: Structured associate hiring exists; competitive | E32: NYC office network; fintech partners; verify current crypto appetite
A34: Keep this lane in quiet channels during the EB cycle: CVF, Galaxy and Broadhaven relationships, and CVC coffees. Never signal the venture endgame in Tier 1 IB conversations. Non-NYC entries (Castle Island, Pantera, Kraken/Coinbase Ventures) are kept for relationship reasons; the full NYC universe is on the VC Fund Database tab. Rows 21-30 added Aug 22, 2026 from general knowledge (Jan 2026 horizon), not the verified research - verify before citing. Global fund universe on the VC Universe tab. Rows 31-32 (a16z crypto, Index Ventures) added for NYC-office reachability.

Sheet VC Fund Database
A1: NYC Crypto VC Fund Database: Full Detail (verified Aug 2026)
A2: Every fund from the Aug 22, 2026 deep research at full fidelity: complete fund lineages, founders, LPs, and 2025-26 deal activity | Sections: NYC crypto-native, bicoastal, generalists, corporate/metro, excluded
A4: Fund | B4: HQ / Main Location | C4: NYC Presence | D4: Status | E4: Founded | F4: Founders & Key People | G4: Fund History (all vehicles) | H4: Strategy & Checks | I4: Thesis / Focus | J4: Portfolio | K4: Recent Activity 2025-26 | L4: LPs / Backers | M4: Engagement Hooks | N4: Priority | O4: Notes / Caveats
A5: CoinFund | B5: Brooklyn, NY | C5: HQ | D5: Active | E5: 2015 | F5: Jake Brukhman (Managing Partner/CEO), Aleksandr Bulkin (co-founder), Alex Felix (Managing Partner/CIO); registered investment adviser | G5: $550M+ raised over 18 months across vehicles: $158M early-stage fund (2023, above its $125M target); Ventures I $300M (2022, Series A focus); Seed IV; deploying from Fund III and other vehicles in 2025-26 | H5: Pre-seed through growth; equity + liquid tokens; network lifecycle investing approach | I5: DeFi, infrastructure, AI agents, market structure, stablecoins/payments | J5: Solana, Polygon, Dapper Labs, Blockdaemon | K5: Recent deals: Veda, Dakota, Ether.fi, Irys, Kadena, Trace Finance, Pluralis | L5: Not disclosed | M5: Active research and publishing, partner podcasts, regulatory engagement, careers page | N5: S1 | O5: RIA registration is an institutional-credibility marker in this set
A6: Archetype | B6: New York, NY | C6: HQ | D6: Active | E6: 2021 | F6: Ash Egan (Founder/GP; co-launched ConsenSys Ventures, ex-Accomplice); Katherine Wu (ex-Coinbase Ventures) | G6: $55M debut fund (2021); Fund II $155M (2022); Fund III $100M+ total commitments (Sep 2025); ~$350M reported assets | H6: Concentrated, high-conviction first check to Series A; equity + liquid positions (holds Solana and Ethereum) | I6: Onchain social, stablecoins, payments infrastructure, modular stacks, crypto x AI, DePIN | J6: Privy (acquired by Stripe), Rated, US Bitcoin Corp; Egan backed Chainalysis pre-Archetype | K6: Fund III close Sep 2025 | L6: Pensions, endowments, sovereign wealth funds, funds of funds, family offices | M6: Archebyte podcast, NYC in-person events, content platform | N6: S1 | O6: Egan frames the deliberately small Fund III as buying extreme selectivity and conviction per team
A7: Variant | B7: Brooklyn, NY (1027 Grand St) | C7: HQ | D7: Active | E7: 2020 | F7: Jesse Walden (ex-a16z crypto); Li Jin (co-GP; her Atelier Ventures merged in) | G7: $22.5M (2020); $110M (2021); Fund III $450M total, split $150M seed + $300M opportunity (2022); Variant 4 $222M (Jun 2026) | H7: Pre-seed/seed; equity + tokens | I7: Ownership economy; Variant 4 reframed around autonomy (crypto x AI) | J7: Uniswap, Phantom, Magic Eden, Mirror, Zora, Foundation, Flashbots, Blockaid | K7: Variant 4 close Jun 2026 | L7: Not disclosed | M7: Heavy research and writing cadence; thesis essays | N7: S1 | O7: Walden's view: within four years crypto investor will be as generic a label as internet investor
A8: Galaxy Ventures | B8: New York, NY | C8: HQ | D8: Active | E8: Fund I 2024-25; platform investing since 2018 | F8: Will Nuelle and Mike Giampapa (fund leads); affiliate of Galaxy (Nasdaq: GLXY; Mike Novogratz) | G8: Fund I $175M+ final close (Jun 2025), above its $150M target; first external venture capital after 120+ balance-sheet investments since 2018 | H8: Early-stage equity plus co-investment; ~30 companies; $3-5M checks | I8: Stablecoins, payments, tokenization, and supporting infrastructure | J8: Ethena, Monad, Plume, 1Money, DoubleZero, Citrea, Arch Lending; balance-sheet legacy: Pyth, Chaos Labs, Fireblocks, Messari | K8: Deploying Fund I | L8: Institutional investors, family offices, fund-of-funds, strategic corporates (names undisclosed) | M8: Galaxy Research; platform team; ~550-person institutional footprint | N8: S1 | O8: Exits include Tagomi and Bison Trails, both to Coinbase; Novogratz cast the above-target close in a hard market as proof of edge
A9: 6th Man Ventures | B9: New York, NY | C9: HQ | D9: Active | E9: 2021 | F9: Mike Dudas (co-founder of The Block), Serge Kassardjian | G9: Fund II $145M (~2022) | H9: Pre-seed to Series A; equity + tokens; checks up to $4-5M; roughly one deal per month; ~50% Solana-weighted | I9: Consumer crypto, apps, infrastructure, gaming, media | J9: Magic Eden, io.net, Livepeer, Pump.fun | K9: Recent: Veera, worm.wtf, Inversion | L9: LPs included Galaxy Vision Hill; Marc Andreessen, Chris Dixon, and Bill Ackman invested personally | M9: Dudas is highly public on X; Breakpoint keynotes | N9: S1
A10: Placeholder | B10: New York, NY | C10: HQ | D10: Active (slower) | E10: 2017 | F10: Chris Burniske, Joel Monegro (both ex-USV lineage); Brad Burnham (venture partner); Mario Laul (research) | G10: ~$150M managed | H10: Venture + public-market liquid hybrid; long-hold; 75+ investments | I10: Thesis-driven protocol investing | J10: Ethereum, Solana, Celestia, Monad, Aleo, Eclipse, Backpack, Squads, Tensor, Jito | K10: 1-2 new deals per year recently | L10: Not disclosed | M10: Extensive public research library; partner podcasts; Burniske's cryptoasset valuation frameworks | N10: S2 | O10: Iconic thesis shop; deployment pace is the tradeoff
A11: Hivemind Capital | B11: New York, NY | C11: HQ | D11: Active (hybrid) | E11: 2021 | F11: Matt Zhang (ex-Citi head of structured products trading); Richard Skeet (London; co-lead, runs the liquid platform) | G11: Launched with a $1.5B multi-strategy mandate (venture, liquid staking/yield, trading, play-to-earn gaming); Liquid Opportunity Fund $300M target (2023); Digital Culture Fund ~$50M target (2024, digital art) | H11: Hybrid venture + liquid + trading; real venture sleeve | I11: Multi-strategy digital assets | J11: Varied | L11: Not disclosed | M11: Institutional profile; less founder-facing | N11: S3 | O11: NYC HQ but liquid investing reports to London
A12: Blockchange Ventures | B12: New York, NY | C12: HQ | D12: Active | E12: Fall 2017 | F12: Ken Seiff (MP; ex-Bluefly, Beanstalk Ventures); Caroline Kassie; Dr. Gavin Wood (part-time GP); Rob Schmults (GP); Janice Chan (CFO); Jon Freedman (COO/CLO) | G12: Multiple funds across the Fund I to IV era | H12: Early-stage; equity + tokens | I12: Base layers and L1s | J12: Solana, Polkadot, Near, Flow, Dapper Labs, Figure, Axelar, Arbitrum, Zama | K12: ~62 active positions; 7 new investments in the trailing 12 months as of mid-2026 | L12: Not disclosed | M12: Seiff accessible via podcasts (The Defiant) | N12: S2 | O12: Gavin Wood's part-time GP role is an unusual signal
A13: North Island Ventures | B13: New York, NY | C13: HQ | D13: Active | E13: 2020 | F13: Travis Scher (ex-DCG VP of investments), James Hutchins (ex-Coatue research), Glenn Hutchins (Silver Lake co-founder; Chairman) | G13: Fund I ~$72M debut; Fund II $125M (2022); ~$300M AUM | H13: Early-stage; $250K-3M initial checks; 30-40 companies per fund; equity + tokens | I13: Interoperability (network of networks), DeFi, stablecoin payments, onchain neobanking | J13: Axelar, BCB Group, Dapper Labs, Flow, Immunefi, Polymer, Figure, Ether.fi, Utila | L13: Not disclosed | M13: Scher is public via podcasts and X; the firm has advertised associate hiring | N13: S2 | O13: The associate-hiring history makes this a live seat to watch, not just a coffee
A14: Portal Ventures | B14: New York, NY | C14: HQ | D14: Active | E14: 2022 | F14: Evan Fisher (ex-Insight Partners, ex-Goldman; Forbes 30 Under 30; Michigan Ross BBA '17); Catrina Wang (GP) | G14: Fund I $35-40M (2022); Fund II $75M closed late 2024, oversubscribed against ~$90M of interest | H14: Pre-seed lead investor; equity + tokens | I14: Fundamentals-driven protocol and business-model thesis; current theme: crypto rails for latent markets | J14: Uranium Digital | K14: Fund II deploying | L14: Backers include Chris Dixon and Marc Andreessen personally, and KKR's Henry Kravis | M14: Fisher's writing and podcasts; hires early-career | N14: S1 | O14: The most MBA-legible investment framing in the NYC set
A15: Reciprocal Ventures | B15: New York, NY (24 W 25th St) | C15: HQ | D15: Active (raising III) | E15: 2016 | F15: Michael Steinberg (ex-SAC/Point72 PM); Craig Burel (GP) | G15: Fund II $68.5M (2022); Fund III raising up to $100M, in market from early 2025; ~$201M AUM | H15: Pre-seed/seed; equity + tokens | I15: DeFi, institutional capital markets, web3 stack, payments | J15: Solana (seed), The Graph, TrueX, Coinflow Labs | K15: Fund III in market | L15: Not disclosed | M15: Diffusion thesis research; partner writing | N15: S2
A16: M31 Capital | B16: New York, NY | C16: HQ | D16: Active (liquid-heavy) | E16: 2020 | F16: Nathan Montone; offices in Scottsdale, SF, Shanghai, Seoul, Delhi, San Juan | G16: ~$100M Web3 Opportunity Fund (Oct 2022, liquid venture); Bitcoin fund; DeFi fund; M31 Ventures arm | H16: Multi-strategy; venture arm invests equity + tokens | I16: Broad web3 | J16: Huddle01, Euler, Elsa | K16: Latest venture deal: Euler (Jul 2025) | L16: Not disclosed | M16: Modest venture cadence | N16: S3 | O16: Hybrid and liquid-heavy; venture is a sleeve
A17: Dragonfly | B17: NYC + Singapore (legal HQ Oakland/SF per some filings) | C17: Major office | D17: Active | E17: 2018 | F17: Founded by Alex Pack and Bo Feng; Haseeb Qureshi (Managing Partner); GPs Rob Hadick, Tom Schmidt | G17: Fund IV $650M (Feb 2026), 30% above its $500M target, matching Fund III (2022); ~$4B total AUM; acquired Metastable, one of the oldest crypto hedge funds | H17: Seed through Series B+; $3-30M checks; equity + liquid | I17: 2025-26 pivot toward financial infrastructure, stablecoins, real-world assets, onchain finance | J17: Polymarket, Ethena, Rain, Mesh, Avalanche, Agora | K17: Fund IV close Feb 2026 | L17: Not disclosed | M17: The Chopping Block podcast; research | N17: S1 | O17: Caveat: DOJ signaled possible charges in 2025 tied to a 2020 Tornado Cash investment involving GP Tom Schmidt; Qureshi noted the raise landed amid deep bear-market gloom
A18: a16z crypto | B18: Menlo Park HQ; NYC office | C18: Office | D18: Active | E18: 2018 | F18: Chris Dixon (founder/lead; Columbia BA and MA in philosophy, HBS MBA); GPs Ali Yahya, Guy Wuollet, Eddy Lazzarin (newly promoted) | G18: Crypto Fund 5 $2.2B (May 2026); $9.8B total crypto capital | H18: Seed to growth; $10-60M checks; equity + tokens | I18: Fund 5 targets stablecoins, tokenization, perpetual futures, prediction markets, and AI agents; deep CLARITY Act and GENIUS Act policy engagement | J18: Coinbase, Uniswap, OpenSea, Solana | K18: Crypto Fund 5 close May 2026 | L18: Not disclosed | M18: Crypto Startup School accelerator; a16z crypto research; State of Crypto report; active recruiting | N18: S2 | O18: Highly competitive; the Dixon Columbia tie is a legitimate hook
A19: 1kx | B19: Berlin (some databases list New York) | C19: Partners only | D19: Active | E19: 2017-18 | F19: Lasse Clausen, Christopher Heymann | G19: $75M fund closed Mar 2024 | H19: Seed/A; token-network specialist; equity + tokens | I19: Token networks | J19: Celestia, Arweave, Solana, Reown/WalletConnect, LI.FI, Layer3 | L19: Not disclosed | N19: Monitor | O19: Should not be counted as an NYC fund in practice
A20: Lightspeed Faction | B20: Menlo Park / SF | C20: No | D20: Active | E20: 2023 | F20: Sam Harrison, Banafsheh Fathieh | G20: $285M inaugural fund (2023) | H20: Early-stage crypto | L20: Lightspeed-affiliated | N20: Exclude | O20: West Coast; on the map only to close the question of whether it belongs here
A21: Union Square Ventures | B21: New York, NY | C21: HQ | D21: Active | E21: 2003-04 | F21: Fred Wilson, Brad Burnham (founders) | G21: Last core fund $275M plus $350M opportunity fund (2022, $625M total); small funds by design | H21: Series A-centric equity; collaborative decision-making | I21: Thesis 3.0; crypto since 2013 (first bet Coinbase); 25+ web3 positions | J21: Coinbase, Uniswap, Polygon, Helium, Dapper | K21: Led a 2025 prediction-market startup round alongside Coinbase Ventures | L21: Not disclosed | M21: USV thesis blog; Fred Wilson's AVC; alumni lineage runs to Placeholder (Monegro, Burniske era) | N21: S1 | O21: They reward writing; written outreach plays to this
A22: Fintech Collective | B22: New York, NY (200 Park Ave S) | C22: HQ | D22: Active | E22: 2012 | F22: Brooks Gibbins, Gareth Jones | G22: ~$500M AUM; 7 funds; 171 investments; 14 exits | H22: Seed/A; $500K-4M checks; equity | I22: Fintech + DeFi crossover; stablecoins, payments, capital markets DNA | J22: 171 investments (individual crypto names not detailed in the research) | L22: Not disclosed | M22: Newsletters (The Dollar's New Avatar; Stablecoins Take the Lead); Layer One podcast; adjacent to the Stablecon NYC conference | N22: S1 | O22: Best pure stablecoins/payments thesis fit in the city
A23: RRE Ventures | B23: New York, NY (130 E 59th) | C23: HQ | D23: Active | E23: 1994 | F23: Long-standing NYC partnership | G23: ~$2.5B AUM; 5 funds | H23: Seed/A; primarily equity | I23: Generalist with a dedicated crypto focus area | J23: Ripple, Paxos, Binance.US, BitPay, Blockdaemon, Abra, Bitnomial | K23: Active in 2025-26 | L23: Not disclosed | M23: NYC generalist brand; crypto focus page | N23: S2 | O23: Bitnomial overlap connects to your Deal Evidence tab
A24: Insight Partners | B24: New York, NY | C24: HQ | D24: Active (crypto episodic) | E24: Growth platform | G24: ~$90B AUM | H24: Growth equity | I24: Crypto-adjacent since 2020 | J24: FTX (historic), TaxBit | L24: Not disclosed | M24: Portal's Evan Fisher is an alumnus | N24: S3 | O24: Crypto is opportunistic, not a practice
A25: Thrive Capital | B25: New York, NY (Puck Building) | C25: HQ | D25: Active (minimal crypto) | E25: 2009 | F25: Josh Kushner | G25: Thrive X $10B (Feb 2026); ~$50-65B AUM | H25: Growth; equity | I25: AI, consumer, enterprise core; crypto peripheral | J25: OpenAI, Stripe, SpaceX; Robinhood on the historic fintech side | L25: Not disclosed | N25: Monitor | O25: Peripheral for this thesis
A26: Deviation Capital (ex-Two Sigma Ventures) | B26: New York, NY | C26: HQ | D26: Active (crypto sleeve) | E26: Rebranded 2025-26 | G26: ~$400M across two 2022 funds; roughly 15% allocated to crypto/web3 | H26: Data-driven generalist; equity | I26: Crypto is a minority sleeve | J26: Pyth, Omni, Rally | L26: Not disclosed | N26: S3 | O26: Verify the rebrand on the firm's site before outreach
A27: Valor Capital Group | B27: New York, NY (+ Rio, Sao Paulo) | C27: HQ | D27: Active (crypto opportunistic) | E27: 2011 | F27: Sobel family | G27: ~$2.2B AUM | H27: US-Brazil/LatAm crossover; equity | I27: Crypto limited and opportunistic | J27: Coinbase, Bitso, Valora | L27: Not disclosed | N27: S2 | O27: Personal edge: your Sao Paulo M&A years and dual citizenship are differentiated here
A28: VanEck Ventures | B28: New York, NY (666 Third Ave) | C28: HQ | D28: Active | E28: Oct 2024 | F28: Wyatt Lonergan, Juan Lopez (both ex-Circle Ventures) | G28: $30M debut fund closed early 2025; related PurposeBuilt Fund launched Jun 2025 (liquid + venture) | H28: Pre-seed/seed; $500K-1M checks; 25-35 companies; equity | I28: Fintech + digital assets + AI; stablecoins and tokenization | J28: Building portfolio | K28: Actively deploying | L28: VanEck (parent) | M28: Media-active partners; direct outreach viable | N28: S1 | O28: The Circle Ventures spinout story is the natural intro line
A29: Circle Ventures | B29: New York, NY (One World Trade Center) | C29: HQ | D29: Active (modest) | E29: CVC | F29: Circle relocated HQ around its Jun 2025 NYSE IPO (CRCL, ~$1.05B raised) | G29: ~9 investments to date | H29: CVC equity | I29: USDC ecosystem | J29: Latest: Zodia Markets (Jul 2025) | L29: Circle (parent) | N29: S3 | O29: Prior VC leads left to found VanEck Ventures, thinning dedicated activity
A30: Consensys / Mesh | B30: Brooklyn, NY | C30: HQ | D30: Active (slower) | E30: Consensys 2014; Mesh 2015, independent 2020 | F30: Joe Lubin (founder) | G30: ~138 equity/token positions; Tachyon and TachyonX accelerators (90+ projects) | H30: CVC equity + tokens; accelerator | I30: Ethereum ecosystem | J30: MetaMask, Gnosis, Aztec, Gitcoin | K30: Mesh new-deal cadence below peak | M30: Tachyon accelerator; ecosystem events | N30: S2 | O30: Consensys IPO delayed to fall 2026 after the Feb 2026 downturn; ARR $150M+; last valued $7B (2022)
A31: Ava Labs / Blizzard Fund | B31: Brooklyn, NY (+ Miami) | C31: HQ | D31: Active | E31: 2018 | F31: Emin Gun Sirer, Kevin Sekniqi, Ted Yin | G31: Ava Labs raised $250M in Dec 2024 (Galaxy-led); Blizzard is a $200M+ Avalanche ecosystem fund (launched 2021) | H31: Ecosystem equity + tokens | I31: Avalanche ecosystem | J31: 150+ Blizzard investments | K31: Still deploying into the ecosystem | L31: Galaxy led the Dec 2024 raise | M31: Ecosystem events | N31: S2
A32: Winklevoss Capital / Gemini | B32: New York, NY (30 W 24th) | C32: HQ | D32: Active | E32: 2012 | F32: Cameron and Tyler Winklevoss | G32: ~172 investments; 24 exits | H32: Family office VC; equity + BTC | I32: Crypto, space, energy, biotech | J32: Broad portfolio | K32: Gemini Space Station (Nasdaq: GEMI) IPO priced at $28, above the $24-26 range, Sep 2025; 15,178,572 Class A shares; ~$425M raised at ~$3.3B valuation; reported 20x oversubscribed; Nasdaq committed a $50M private placement | N32: S3 | O32: Gemini stock later fell sharply; Winklevoss Capital injected $100M at $14/share in May 2026, paid in bitcoin
A33: Republic Capital / Crypto | B33: New York, NY | C33: HQ | D33: Active | E33: Republic 2016; Capital arm 2019 | F33: Organized as Republic Capital (multi-stage VC), Republic Digital (crypto hedge fund), Republic Crypto (advisory) | G33: $2.6B+ deployed across 2,500+ ventures | H33: Multi-stage; equity + tokens | I33: Tokenized assets and retail platform push in 2026 | J33: Broad | K33: Latest Republic Capital deal: Neblio Technologies (Oct 2025) | L33: Backed by Galaxy, Binance, Naspers | M33: Platform events | N33: S2
A34: White Star Capital DAF | B34: New York (DAF team; global firm: London, Paris, Montreal, Toronto, Tokyo, Singapore) | C34: Team | D34: Active (modest cadence) | E34: DAF I 2021 | F34: Sep Alavi (Managing Partner); Eddie Lee, Luke Xiao (DAF team) | G34: DAF I $50M (2021); DAF II $120M first close (2022, Ubisoft anchor) | H34: Seed/A; equity + tokens | I34: DeFi, gaming | J34: Ledn, RedStone, Etherfuse, Kulipa | K34: Latest: Alfred (Jan 2026) | L34: Ubisoft anchored DAF II | N34: S3
